Workbook

Sheet Nhập Hàng
C1: 46096
B2: Vốn | C2: Nhập | D2: Tặng | E2: Thành tiền
A3: Thanh cua trứng Mayo | B3: 13000 | C3: 23 | E3: =C3*B3 -> 299000
A4: 🧀Pate phô mai kéo sợi | B4: 13000 | C4: 12 | E4: =C4*B4 -> 156000
A5: 🐷Heo cao bồi xúc xích | B5: 13000 | C5: 12 | E5: =C5*B5 -> 156000
A6: 🐔Gà tomyum | B6: 13000 | C6: 10 | E6: =C6*B6 -> 130000
A7: 🐔 Gà teriyaki | B7: 13000 | C7: 10 | E7: =C7*B7 -> 130000
A8: 🐮Bò BBQ | B8: 13000 | C8: 25 | E8: =C8*B8 -> 325000
A9: 🦐Tôm đút lò | B9: 13000 | C9: 14 | E9: =C9*B9 -> 182000
A10: 🎏Cá ngừ | B10: 16000 | C10: 15 | E10: =C10*B10 -> 240000
A11: 🥘Chả cá xốt cay | B11: 13000 | C11: 5 | E11: =C11*B11 -> 65000
A12: 🌮 Trứng xúc xích mayo | B12: 13000 | C12: 15 | E12: =C12*B12 -> 195000
A13: 🍣Cá hồi mayo | B13: 13000 | C13: 20 | E13: =C13*B13 -> 260000
A14: 🌭 Xúc xích siêu phomai | B14: 13000 | C14: 139 | E14: =C14*B14 -> 1807000
A15: Tổng | C15: =SUM(C3:C14)+sum(D3:D14) -> 300 | E15: =SUM(E2:E14) -> 3945000
B17: Bán | C17: Nhập | D17: Tặng | E17: Thành tiền
A18: Thanh cua trứng Mayo | B18: 20000 | C18: 23 | E18: =C18*B18 -> 460000
A19: 🧀Pate phô mai kéo sợi | B19: 20000 | C19: 12 | E19: =C19*B19 -> 240000
A20: 🐷Heo cao bồi xúc xích | B20: 20000 | C20: 12 | E20: =C20*B20 -> 240000
A21: 🐔Gà tomyum | B21: 20000 | C21: 10 | E21: =C21*B21 -> 200000
A22: 🐔 Gà teriyaki | B22: 20000 | C22: 10 | E22: =C22*B22 -> 200000
A23: 🐮Bò BBQ | B23: 20000 | C23: 25 | E23: =C23*B23 -> 500000
A24: 🦐Tôm đút lò | B24: 20000 | C24: 14 | E24: =C24*B24 -> 280000
A25: 🎏Cá ngừ | B25: 22000 | C25: 15 | E25: =C25*B25 -> 330000
A26: 🥘Chả cá xốt cay | B26: 20000 | C26: 5 | E26: =C26*B26 -> 100000
A27: 🌮 Trứng xúc xích mayo | B27: 20000 | C27: 15 | E27: =C27*B27 -> 300000
A28: 🍣Cá hồi mayo | B28: 20000 | C28: 20 | E28: =C28*B28 -> 400000
A29: 🌭 Xúc xích siêu phomai | B29: 20000 | C29: 139 | E29: =C29*B29 -> 2780000
A30: Tổng | C30: =SUM(C18:C29)+sum(D18:D29) -> 300 | E30: =SUM(E17:E29) -> 6030000

Sheet Chi Phí
A2: Chi Phí
A4: Cố định | B4: Tổng CP | C4: Đơn giá | D4: Số lượng
D5: 46089 | E5: =D5+1 -> 46090 | F5: =E5+1 -> 46091 | G5: =F5+1 -> 46092 | H5: =G5+1 -> 46093 | I5: =H5+1 -> 46094 | J5: =I5+1 -> 46095 | K5: =J5+1 -> 46096 | L5: 46105
A6: Đồng phục | B6: =C6*sum(D6:L6) -> 1000000 | C6: 200000 | J6: 5
A7: Quầy Kệ | B7: =C7*sum(D7:L7) -> 7000000 | C7: 1000000 | D7: 3 | J7: 4
A8: Tờ Rơi | B8: =C8*sum(D8:L8) -> 0
A9: Túi mù | B9: =C9*sum(D9:L9) -> 0
A10: Lego | B10: =C10*sum(D10:L10) -> 0 | C10: 1000
A11: Lò vi sóng | B11: =C11*sum(D11:L11) -> 5100000 | C11: 1700000 | D11: 1 | F11: 1 | K11: 1
A12: Thùng đá | B12: =C12*sum(D12:L12) -> 1200000 | C12: 300000 | D12: 1 | E12: 1 | F12: 1 | K12: 1
A13: Lò vi sóng 3 | B13: =C13*sum(D13:L13) -> 1450000 | C13: 1450000 | L13: 1
A14: Lò vi sóng 2 | B14: =C14*sum(D14:L14) -> 1700000 | C14: 1700000 | F14: =L13 -> 1
A15: Lò vi sóng 1 | B15: =C15*sum(E14:L14) -> 1650000 | C15: 1650000 | D15: 1
A16: Túi nilon | B16: =C16*sum(D16:L16) -> 860000 | C16: 43000 | L16: 20
A17: Túi mù | B17: =C17*sum(D17:L17) -> 1240000 | C17: =1240000/L17 -> 620 | L17: 2000
B18: =SUM(B5:B17) -> 21200000

Sheet Giá NhậpXuất
A1: Giá
A3: STT | B3: Mặt Hàng | C3: Vốn | D3: Giá bán
A4: 1 | B4: Thanh cua trứng Mayo | C4: 13000 | D4: 20000
A5: 2 | B5: 🧀Pate phô mai kéo sợi | C5: 13000 | D5: 20000
A6: 3 | B6: 🐷Heo cao bồi xúc xích | C6: 13000 | D6: 20000
A7: 4 | B7: 🐔Gà tomyum | C7: 13000 | D7: 20000
A8: 5 | B8: 🐔 Gà teriyaki | C8: 13000 | D8: 20000
A9: 6 | B9: 🐮Bò BBQ | C9: 13000 | D9: 20000
A10: 7 | B10: 🦐Tôm đút lò | C10: 13000 | D10: 20000
A11: 8 | B11: 🎏Cá ngừ | C11: 13000 | D11: 22000
A12: 9 | B12: 🥘Chả cá xốt cay | C12: 13000 | D12: 20000
A13: 10 | B13: 🌮 Trứng xúc xích mayo | C13: 13000 | D13: 20000
A14: 11 | B14: 🍣Cá hồi mayo | C14: 16000 | D14: 20000
A15: 12 | B15: 🌭 Xúc xích siêu phomai | C15: 13000 | D15: 20000
B17: Chi phí/nắm | C17: =sum(C18:C21) -> 1233.3333
B18: Vận chuyển | C18: =100000/1200 -> 83.333333
B19: Quà | C19: 1000
B20: Túi | C20: 50
B21: Điện | C21: 100
B22: Đồ chơi | C22: 3450 | D22: 4099 | E22: 20000
B23: Túi Mù | D23: 1240

Sheet Lương NV
C2: Tuần 8/3 - 13/3
C3: T2 | D3: T3 | E3: T4 | F3: T5 | G3: T6 | H3: Lương/tuần
A4: Họ Tên | C4: 46090 | D4: =C4+1 -> 46091 | E4: =D4+1 -> 46092 | F4: =E4+1 -> 46093 | G4: =F4+1 -> 46094 | J4: 46097 | K4: =J4+1 -> 46098 | L4: =K4+1 -> 46099
A5: Phùng Hà My | B5: S | E5: 50 | G5: 70 | H5: =D6+E5+E6+F6+G5 -> 310
B6: C | D6: 50 | E6: 70 | F6: 70
A7: Ninh Thị Diệu Anh | B7: S | E7: 50 | H7: =D8+E7+F8 -> 170
B8: C | D8: 50 | F8: 70
A9: Hoàng Vân Anh | B9: S | E9: 50 | G9: 70 | H9: 310
B10: C | D10: 50 | E10: 70 | F10: 70
A11: Nguyễn Ánh Hồng | B11: S | H11: 100
B12: C | D12: 50 | F12: 50
A13: Nguyễn Tuấn Định | B13: S | H13: =D14+E14+F14+G14 -> 240
B14: C | D14: 50 | E14: 50 | F14: 70 | G14: 70
A15: Trịnh Thị Ngọc Minh | B15: S | F15: 50 | H15: =E16+F15+F16+G16 -> 240
B16: C | E16: 50 | F16: 70 | G16: 70
A17: Lưu Quỳnh Nga | B17: S | F17: 50 | H17: =F17 -> 50
B18: C
A19: Ngọc Ánh | B19: S | G19: 50 | H19: =G19+F20 -> 100
B20: C | F20: 50
A21: Tạ Thị Ngọc Hà | B21: S | G21: 50 | H21: =G21+F22 -> 100
B22: C | F22: 50
H23: =sum(H5:H22) -> 1620
A27: HV buổi đầu | I27: HV buổi 1,2 | J27: Làm xa | K27: Ca sáng gần | L27: Ca chiều gần
A29: Họ Tên | B29: Ca LV | C29: T2 | D29: T3 | E29: T4 | F29: T5 | G29: T6 | I29: T2 | J29: T3 | K29: T4 | L29: T5 | M29: T6 | O29: T2 | P29: T3 | Q29: T4 | R29: T5 | S29: T6
C30: 46090 | D30: =C30+1 -> 46091 | E30: =D30+1 -> 46092 | F30: =E30+1 -> 46093 | G30: =F30+1 -> 46094 | I30: 46097 | J30: 46098 | K30: 46099 | L30: =K30+1 -> 46100 | M30: =L30+1 -> 46101 | O30: 46104 | P30: =O30+1 -> 46105 | Q30: =P30+1 -> 46106 | R30: =Q30+1 -> 46107 | S30: =R30+1 -> 46108
A31: Phùng Hà My | B31: S | E31: TV | G31: CT | K31: 1 | Q31: 70 | T31: =O31+P31+Q31+R31+S31+O32+P32+Q32+R32+S32 -> 300
B32: C | D32: TV | E32: CT | F32: CT | J32: 1 | K32: 1 | L32: 1 | P32: 70 | Q32: 80 | R32: 80
A33: Ninh Thị Diệu Anh | B33: S | E33: TV | K33: 1 | Q33: 70 | T33: =O33+P33+Q33+R33+S33+O34+P34+Q34+R34+S34 -> 140
B34: C | D34: TV | F34: CT | L34: 1 | R34: 70
A35: Hoàng Vân Anh | B35: S | E35: TV | G35: CT | K35: 1 | Q35: 70 | T35: =O35+P35+Q35+R35+S35+O36+P36+Q36+R36+S36 -> 210
B36: C | D36: TV | E36: CT | F36: CT | J36: 1 | K36: 1 | L36: 1 | P36: 70 | Q36: 70
A37: Nguyễn Ánh Hồng | B37: S
B38: C | D38: TV | F38: TV
A39: Dương Tuấn Định | B39: S | I39: 1 | K39: 1 | O39: 70 | Q39: 70 | T39: =O39+P39+Q39+R39+S39+O40+P40+Q40+R40+S40 -> 350
B40: C | D40: TV | E40: TV | F40: CT | G40: CT | I40: 1 | K40: 1 | L40: 1 | O40: 70 | Q40: 70 | R40: 70
A41: Trịnh Thị Ngọc Minh | B41: S | F41: TV | I41: 1 | K41: 1 | L41: 1 | O41: 70 | Q41: 70 | R41: 70 | T41: =O41+P41+Q41+R41+S41+O42+P42+Q42+R42+S42 -> 350
B42: C | E42: TV | F42: CT | G42: CT | K42: 1 | L42: 1 | Q42: 70 | R42: 70
A43: Lưu Quỳnh Nga | B43: S | F43: TV | L43: 1 | M43: 1 | R43: 70 | S43: 70 | T43: =O43+P43+Q43+R43+S43+O44+P44+Q44+R44+S44+N44 -> 310
B44: C | I44: 1 | J44: 1 | N44: 50 | O44: 50 | P44: 70
A45: Ngọc Ánh | B45: S | G45: TV | M45: 1 | S45: 70 | T45: =O45+P45+Q45+R45+S45+O46+P46+Q46+R46+S46 -> 290
...

Sheet Nhập hàng New
A1: Ngày Nhập | B1: Loại hàng | C1: Số lượng Nhập | D1: Thành Tiền | E1: Đơn giá | G1: Tặng | I1: Loại Hàng | J1: Tổng Nhập | K1: Đã Xuất | L1: Tồn kho tổng | M1: Trạng Thái
A2: 46103 | B2: ='Giá NhậpXuất'!B4 -> Thanh cua trứng Mayo | C2: 35 | D2: =C2*'Giá NhậpXuất'!$C$4 -> 455000 | E2: =D2/C2 -> 13000 | I2: Thanh cua trứng Mayo | J2: {=IF(I2:I13="",, SUMIF(B:B, I2:I13, C:C))} -> 1889 | K2: {=IF(I2:I13="",, SUMIF('Nhật ký bán hàng T3'!F:F, I2:I13, 'Nhật ký bán hàng T3'!H:H))} -> 253 | L2: {=IF(I2:I13="",, J2:J13 - K2:K13)} -> 1636 | M2: {=IF(L2:L13="",, IF(L2:L13<10, "🚨 NHẬP GẤP!", IF(L2:L13<15, "⚠️ SẮP HẾT", "✅ AN TOÀN")))} -> ✅ AN TOÀN
A3: 46103 | B3: ='Giá NhậpXuất'!B5 -> 🧀Pate phô mai kéo sợi | C3: 15 | D3: =C3*'Giá NhậpXuất'!C5 -> 195000 | E3: =D3/C3 -> 13000 | I3: 🧀Pate phô mai kéo sợi | J3: 1077 | K3: 132 | L3: 945 | M3: ✅ AN TOÀN
A4: 46103 | B4: ='Giá NhậpXuất'!B6 -> 🐷Heo cao bồi xúc xích | C4: 15 | D4: =C4*'Giá NhậpXuất'!C6 -> 195000 | E4: =D4/C4 -> 13000 | I4: 🐷Heo cao bồi xúc xích | J4: 955 | K4: 109 | L4: 846 | M4: ✅ AN TOÀN | O4: back | R4: treo | S4: treo
A5: 46103 | B5: ='Giá NhậpXuất'!B7 -> 🐔Gà tomyum | C5: 20 | D5: =C5*'Giá NhậpXuất'!C7 -> 260000 | E5: =D5/C5 -> 13000 | I5: 🐔Gà tomyum | J5: 952 | K5: 111 | L5: 841 | M5: ✅ AN TOÀN | O5: 300 lego | R5: 5 quầy | S5: 5 đồng phục
A6: 46103 | B6: ='Giá NhậpXuất'!B8 -> 🐔 Gà teriyaki | C6: 25 | D6: =C6*'Giá NhậpXuất'!C8 -> 325000 | E6: =D6/C6 -> 13000 | I6: 🐔 Gà teriyaki | J6: 1589 | K6: 179 | L6: 1410 | M6: ✅ AN TOÀN
A7: 46103 | B7: ='Giá NhậpXuất'!B9 -> 🐮Bò BBQ | C7: 40 | D7: =C7*'Giá NhậpXuất'!C9 -> 520000 | E7: =D7/C7 -> 13000 | I7: 🐮Bò BBQ | J7: 1833 | K7: 217 | L7: 1616 | M7: ✅ AN TOÀN
A8: 46103 | B8: ='Giá NhậpXuất'!B10 -> 🦐Tôm đút lò | C8: 22 | D8: =C8*'Giá NhậpXuất'!C10 -> 286000 | E8: =D8/C8 -> 13000 | I8: 🦐Tôm đút lò | J8: 1084 | K8: 121 | L8: 963 | M8: ✅ AN TOÀN
A9: 46103 | B9: ='Giá NhậpXuất'!B11 -> 🎏Cá ngừ | C9: 10 | D9: =C9*'Giá NhậpXuất'!C11 -> 130000 | E9: =D9/C9 -> 13000 | I9: 🎏Cá ngừ | J9: 863 | K9: 68 | L9: 795 | M9: ✅ AN TOÀN
A10: 46103 | B10: ='Giá NhậpXuất'!B12 -> 🥘Chả cá xốt cay | C10: 10 | D10: =C10*'Giá NhậpXuất'!C12 -> 130000 | E10: =D10/C10 -> 13000 | I10: 🥘Chả cá xốt cay | J10: 928 | K10: 80 | L10: 848 | M10: ✅ AN TOÀN
A11: 46103 | B11: ='Giá NhậpXuất'!B13 -> 🌮 Trứng xúc xích mayo | C11: 20 | D11: =C11*'Giá NhậpXuất'!C13 -> 260000 | E11: =D11/C11 -> 13000 | I11: 🌮 Trứng xúc xích mayo | J11: 1302 | K11: 125 | L11: 1177 | M11: ✅ AN TOÀN
A12: 46103 | B12: ='Giá NhậpXuất'!B14 -> 🍣Cá hồi mayo | C12: 10 | D12: =C12*'Giá NhậpXuất'!C14 -> 160000 | E12: =D12/C12 -> 16000 | I12: 🍣Cá hồi mayo | J12: 940 | K12: 85 | L12: 855 | M12: ✅ AN TOÀN
A13: 46103 | B13: ='Giá NhậpXuất'!B15 -> 🌭 Xúc xích siêu phomai | C13: 180 | D13: =C13*'Giá NhậpXuất'!C15 -> 2340000 | E13: =D13/C13 -> 13000 | I13: 🌭 Xúc xích siêu phomai | J13: 10202 | K13: 1113 | L13: 9089 | M13: ✅ AN TOÀN
C14: =sum(C2:C13) -> 402 | D14: =sum(D2:D13) -> 5256000
A15: =A2+1 -> 46104 | B15: Thanh cua trứng Mayo | C15: 35 | D15: =C15*'Giá NhậpXuất'!$C4 -> 455000 | E15: =D15/C15 -> 13000
A16: =A3+1 -> 46104 | B16: 🧀Pate phô mai kéo sợi | C16: 20 | D16: =C16*'Giá NhậpXuất'!$C5 -> 260000 | E16: =D16/C16 -> 13000
A17: =A4+1 -> 46104 | B17: 🐷Heo cao bồi xúc xích | C17: 15 | D17: =C17*'Giá NhậpXuất'!$C6 -> 195000 | E17: =D17/C17 -> 13000
A18: =A5+1 -> 46104 | B18: 🐔Gà tomyum | C18: 20 | D18: =C18*'Giá NhậpXuất'!$C7 -> 260000 | E18: =D18/C18 -> 13000
A19: =A6+1 -> 46104 | B19: 🐔 Gà teriyaki | C19: 25 | D19: =C19*'Giá NhậpXuất'!$C8 -> 325000 | E19: =D19/C19 -> 13000
A20: =A7+1 -> 46104 | B20: 🐮Bò BBQ | C20: 35 | D20: =C20*'Giá NhậpXuất'!$C9 -> 455000 | E20: =D20/C20 -> 13000
A21: =A8+1 -> 46104 | B21: 🦐Tôm đút lò | C21: 25 | D21: =C21*'Giá NhậpXuất'!$C10 -> 325000 | E21: =D21/C21 -> 13000
A22: =A9+1 -> 46104 | B22: 🎏Cá ngừ | C22: 10 | D22: =C22*'Giá NhậpXuất'!$C11 -> 130000 | E22: =D22/C22 -> 13000
A23: =A10+1 -> 46104 | B23: 🥘Chả cá xốt cay | C23: 10 | D23: =C23*'Giá NhậpXuất'!$C12 -> 130000 | E23: =D23/C23 -> 13000
A24: =A11+1 -> 46104 | B24: 🌮 Trứng xúc xích mayo | C24: 20 | D24: =C24*'Giá NhậpXuất'!$C13 -> 260000 | E24: =D24/C24 -> 13000 | I24: tôm | J24: 10
A25: =A12+1 -> 46104 | B25: 🍣Cá hồi mayo | C25: 15 | D25: =C25*'Giá NhậpXuất'!$C14 -> 240000 | E25: =D25/C25 -> 16000 | I25: hồi | J25: 6
A26: =A13+1 -> 46104 | B26: 🌭 Xúc xích siêu phomai | C26: 170 | D26: =C26*'Giá NhậpXuất'!$C15 -> 2210000 | E26: =D26/C26 -> 13000 | I26: bò | J26: 4
C27: =sum(C15:C26) -> 400 | D27: =sum(D15:D26) -> 5245000 | I27: gà yum | J27: 1
A28: 46105 | B28: Thanh cua trứng Mayo | C28: 40 | D28: =C28*'Giá NhậpXuất'!$C$4 -> 520000 | E28: =D28/C28 -> 13000 | I28: heo | J28: 1
A29: 46105 | B29: 🧀Pate phô mai kéo sợi | C29: 25 | D29: =C29*'Giá NhậpXuất'!$C$5 -> 325000 | E29: =D29/C29 -> 13000 | I29: gà terri | J29: 3
A30: 46105 | B30: 🐷Heo cao bồi xúc xích | C30: 20 | D30: =C30*'Giá NhậpXuất'!$C$6 -> 260000 | E30: =D30/C30 -> 13000
A31: 46105 | B31: 🐔Gà tomyum | C31: 25 | D31: =C31*'Giá NhậpXuất'!$C$7 -> 325000 | E31: =D31/C31 -> 13000
A32: 46105 | B32: 🐔 Gà teriyaki | C32: 32 | D32: =C32*'Giá NhậpXuất'!$C$8 -> 416000 | E32: =D32/C32 -> 13000
A33: 46105 | B33: 🐮Bò BBQ | C33: 45 | D33: =C33*'Giá NhậpXuất'!$C$9 -> 585000 | E33: =D33/C33 -> 13000
A34: 46105 | B34: 🦐Tôm đút lò | C34: 30 | D34: =C34*'Giá NhậpXuất'!$C$10 -> 390000 | E34: =D34/C34 -> 13000
A35: 46105 | B35: 🎏Cá ngừ | C35: 12 | D35: =C35*'Giá NhậpXuất'!$C$11 -> 156000 | E35: =D35/C35 -> 13000
A36: 46105 | B36: 🥘Chả cá xốt cay | C36: 12 | D36: =C36*'Giá NhậpXuất'!$C$12 -> 156000 | E36: =D36/C36 -> 13000
A37: 46105 | B37: 🌮 Trứng xúc xích mayo | C37: 25 | D37: =C37*'Giá NhậpXuất'!$C$13 -> 325000 | E37: =D37/C37 -> 13000 | N37: Tồn | O37: XL | R37: XĐ. Sau | S37: VTD | T37: CN A | U37: CN B | AA37: hàng mới | AB37: Tồn sáng | AC37: VTD | AD37: CN A
A38: 46105 | B38: 🍣Cá hồi mayo | C38: 15 | D38: =C38*'Giá NhậpXuất'!$C$14 -> 240000 | E38: =D38/C38 -> 16000 | L38: Thanh cua trứng Mayo | M38: 15 | N38: =M38-sum(O38:U38) -> 5 | S38: 5 | U38: 5 | X38: Thanh cua trứng Mayo | Y38: =AA38+AB38 -> 11 | AA38: 8 | AB38: ='Nhật ký bán hàng T3'!I734+'Nhật ký bán hàng T3'!I758 -> 3 | AC38: 7 | AD38: 4 | AE38: =Y38-AC38-AD38 -> 0
A39: 46105 | B39: 🌭 Xúc xích siêu phomai | C39: 220 | D39: =C39*'Giá NhậpXuất'!$C$15 -> 2860000 | E39: =D39/C39 -> 13000 | L39: 🧀Pate phô mai kéo sợi | M39: 10 | N39: =M39-sum(O39:U39) -> 2 | S39: 4 | U39: 4 | X39: 🧀Pate phô mai kéo sợi | Y39: =AA39+AB39 -> 2 | AA39: 2 | AB39: ='Nhật ký bán hàng T3'!I735+'Nhật ký bán hàng T3'!I759 -> 0 | AC39: 1 | AD39: 1 | AE39: =Y39-AC39-AD39 -> 0
C40: =sum(C28:C39) -> 501 | D40: =sum(D28:D39) -> 6558000 | L40: 🐷Heo cao bồi xúc xích | M40: 6 | N40: =M40-sum(O40:U40) -> 0 | S40: 3 | U40: 3 | X40: 🐷Heo cao bồi xúc xích | Y40: =AA40+AB40 -> 3 | AB40: ='Nhật ký bán hàng T3'!I736+'Nhật ký bán hàng T3'!I760 -> 3 | AC40: 1 | AD40: 2 | AE40: =Y40-AC40-AD40 -> 0
...

Sheet Nhật ký bán hàng T4
A1: STT | B1: Ngày | C1: Ca Bán | D1: Điểm bán | E1: NV Bán | F1: Loại hàng | G1: Tồn đầu | H1: Hàng Bán Mới | I1: Tồn Cuối | J1: Hàng Lỗi | K1: Bán Thực | L1: Doanh Thu
A2: 1 | B2: 46118 | C2: Sáng | D2: VTD | E2: Nguyễn Thị Kim Ngân | F2: Thanh cua trứng Mayo | H2: 7 | I2: 0 | K2: {=IF(E2:E1072="NGHỈ BÁN", 0, IF(F2:F1072="",, G2:G1072 + H2:H1072 - I2:I1072 - J2:J1072))} -> 7 | L2: {=IF(E2:E1072="NGHỈ BÁN", 0, IF(K2:K1072="",, IF(ISNUMBER(SEARCH("Cá hồi", F2:F1072)), K2:K1072*22000, K2:K1072*20000)))} -> 140000
A3: 2 | B3: 46118 | C3: Sáng | D3: VTD | E3: Nguyễn Thị Kim Ngân | F3: 🧀Pate phô mai kéo sợi | H3: 3 | I3: 0 | K3: 3 | L3: 60000
A4: 3 | B4: 46118 | C4: Sáng | D4: VTD | E4: Nguyễn Thị Kim Ngân | F4: 🐷Heo cao bồi xúc xích | H4: 3 | I4: 0 | K4: 3 | L4: 60000
A5: 4 | B5: 46118 | C5: Sáng | D5: VTD | E5: Nguyễn Thị Kim Ngân | F5: 🐔Gà tomyum | H5: 3 | I5: 0 | K5: 3 | L5: 60000
A6: 5 | B6: 46118 | C6: Sáng | D6: VTD | E6: Nguyễn Thị Kim Ngân | F6: 🐔 Gà teriyaki | H6: 5 | I6: 0 | K6: 5 | L6: 100000
A7: 6 | B7: 46118 | C7: Sáng | D7: VTD | E7: Nguyễn Thị Kim Ngân | F7: 🐮Bò BBQ | H7: 5 | I7: 0 | K7: 5 | L7: 100000
A8: 7 | B8: 46118 | C8: Sáng | D8: VTD | E8: Nguyễn Thị Kim Ngân | F8: 🦐Tôm đút lò | H8: 2 | I8: 0 | K8: 2 | L8: 40000
A9: 8 | B9: 46118 | C9: Sáng | D9: VTD | E9: Nguyễn Thị Kim Ngân | F9: 🎏Cá ngừ | H9: 3 | I9: 0 | K9: 3 | L9: 60000
A10: 9 | B10: 46118 | C10: Sáng | D10: VTD | E10: Nguyễn Thị Kim Ngân | F10: 🥘Chả cá xốt cay | H10: 7 | I10: 0 | K10: 7 | L10: 140000
A11: 10 | B11: 46118 | C11: Sáng | D11: VTD | E11: Nguyễn Thị Kim Ngân | F11: 🌮 Trứng xúc xích mayo | H11: 3 | I11: 0 | K11: 3 | L11: 60000
A12: 11 | B12: 46118 | C12: Sáng | D12: VTD | E12: Nguyễn Thị Kim Ngân | F12: 🍣Cá hồi mayo | H12: 3 | I12: 0 | K12: 3 | L12: 66000
A13: 12 | B13: 46118 | C13: Sáng | D13: VTD | E13: Nguyễn Thị Kim Ngân | F13: 🌭 Xúc xích siêu phomai | H13: 30 | I13: 0 | K13: 30 | L13: 600000
A14: 13 | B14: 46118 | C14: Chiều | D14: VTD | E14: Trịnh Thị Ngọc Minh | F14: Thanh cua trứng Mayo | G14: =I2 -> 0 | K14: 0 | L14: 0
A15: 14 | B15: 46118 | C15: Chiều | D15: VTD | E15: Trịnh Thị Ngọc Minh | F15: 🧀Pate phô mai kéo sợi | G15: =I3 -> 0 | K15: 0 | L15: 0
A16: 15 | B16: 46118 | C16: Chiều | D16: VTD | E16: Trịnh Thị Ngọc Minh | F16: 🐷Heo cao bồi xúc xích | G16: =I4 -> 0 | K16: 0 | L16: 0
A17: 16 | B17: 46118 | C17: Chiều | D17: VTD | E17: Trịnh Thị Ngọc Minh | F17: 🐔Gà tomyum | G17: =I5 -> 0 | K17: 0 | L17: 0
A18: 17 | B18: 46118 | C18: Chiều | D18: VTD | E18: Trịnh Thị Ngọc Minh | F18: 🐔 Gà teriyaki | G18: =I6 -> 0 | K18: 0 | L18: 0
A19: 18 | B19: 46118 | C19: Chiều | D19: VTD | E19: Trịnh Thị Ngọc Minh | F19: 🐮Bò BBQ | G19: =I7 -> 0 | K19: 0 | L19: 0
A20: 19 | B20: 46118 | C20: Chiều | D20: VTD | E20: Trịnh Thị Ngọc Minh | F20: 🦐Tôm đút lò | G20: =I8 -> 0 | K20: 0 | L20: 0
A21: 20 | B21: 46118 | C21: Chiều | D21: VTD | E21: Trịnh Thị Ngọc Minh | F21: 🎏Cá ngừ | G21: =I9 -> 0 | K21: 0 | L21: 0
A22: 21 | B22: 46118 | C22: Chiều | D22: VTD | E22: Trịnh Thị Ngọc Minh | F22: 🥘Chả cá xốt cay | G22: =I10 -> 0 | K22: 0 | L22: 0
A23: 22 | B23: 46118 | C23: Chiều | D23: VTD | E23: Trịnh Thị Ngọc Minh | F23: 🌮 Trứng xúc xích mayo | G23: =I11 -> 0 | K23: 0 | L23: 0
A24: 23 | B24: 46118 | C24: Chiều | D24: VTD | E24: Trịnh Thị Ngọc Minh | F24: 🍣Cá hồi mayo | G24: =I12 -> 0 | K24: 0 | L24: 0
A25: 24 | B25: 46118 | C25: Chiều | D25: VTD | E25: Trịnh Thị Ngọc Minh | F25: 🌭 Xúc xích siêu phomai | G25: =I13 -> 0 | K25: 0 | L25: 0
A26: 25 | B26: 46118 | C26: Sáng | D26: CN A | E26: Thu Hương | F26: Thanh cua trứng Mayo | H26: 7 | I26: 0 | K26: 7 | L26: 140000
A27: 26 | B27: 46118 | C27: Sáng | D27: CN A | E27: Thu Hương | F27: 🧀Pate phô mai kéo sợi | H27: 3 | I27: 0 | K27: 3 | L27: 60000
A28: 27 | B28: 46118 | C28: Sáng | D28: CN A | E28: Thu Hương | F28: 🐷Heo cao bồi xúc xích | H28: 4 | I28: 0 | K28: 4 | L28: 80000
A29: 28 | B29: 46118 | C29: Sáng | D29: CN A | E29: Thu Hương | F29: 🐔Gà tomyum | H29: 3 | I29: 0 | K29: 3 | L29: 60000
A30: 29 | B30: 46118 | C30: Sáng | D30: CN A | E30: Thu Hương | F30: 🐔 Gà teriyaki | H30: 4 | I30: 0 | K30: 4 | L30: 80000
A31: 30 | B31: 46118 | C31: Sáng | D31: CN A | E31: Thu Hương | F31: 🐮Bò BBQ | H31: 6 | I31: 0 | K31: 6 | L31: 120000
A32: 31 | B32: 46118 | C32: Sáng | D32: CN A | E32: Thu Hương | F32: 🦐Tôm đút lò | H32: 3 | I32: 0 | K32: 3 | L32: 60000
A33: 32 | B33: 46118 | C33: Sáng | D33: CN A | E33: Thu Hương | F33: 🎏Cá ngừ | H33: 2 | I33: 0 | K33: 2 | L33: 40000
A34: 33 | B34: 46118 | C34: Sáng | D34: CN A | E34: Thu Hương | F34: 🥘Chả cá xốt cay | H34: 3 | I34: 0 | K34: 3 | L34: 60000
A35: 34 | B35: 46118 | C35: Sáng | D35: CN A | E35: Thu Hương | F35: 🌮 Trứng xúc xích mayo | H35: 4 | I35: 0 | K35: 4 | L35: 80000
A36: 35 | B36: 46118 | C36: Sáng | D36: CN A | E36: Thu Hương | F36: 🍣Cá hồi mayo | H36: 2 | I36: 0 | K36: 2 | L36: 44000
A37: 36 | B37: 46118 | C37: Sáng | D37: CN A | E37: Thu Hương | F37: 🌭 Xúc xích siêu phomai | H37: 30 | K37: 30 | L37: 600000
A38: 37 | B38: 46118 | C38: Chiều | D38: CN A | E38: Lưu Doãn Hoài Nam | F38: Thanh cua trứng Mayo | G38: =I26 -> 0 | K38: 0 | L38: 0
A39: 38 | B39: 46118 | C39: Chiều | D39: CN A | E39: Lưu Doãn Hoài Nam | F39: 🧀Pate phô mai kéo sợi | G39: =I27 -> 0 | K39: 0 | L39: 0
A40: 39 | B40: 46118 | C40: Chiều | D40: CN A | E40: Lưu Doãn Hoài Nam | F40: 🐷Heo cao bồi xúc xích | G40: =I28 -> 0 | K40: 0 | L40: 0
...

Sheet Nhật ký bán hàng T3
A1: STT | B1: Ngày | C1: Ca Bán | D1: Điểm bán | E1: NV Bán | F1: Loại hàng | G1: Tồn đầu | H1: Hàng Bán Mới | I1: Tồn Cuối | J1: Hàng Lỗi | K1: Bán Thực | L1: Doanh Thu
A2: 1 | B2: 46104 | C2: Sáng | D2: XĐ CT | E2: NGHỈ BÁN | F2: Thanh cua trứng Mayo | K2: {=IF(E2:E1072="NGHỈ BÁN", 0, IF(F2:F1072="",, G2:G1072 + H2:H1072 - I2:I1072 - J2:J1072))} -> 0 | L2: {=IF(E2:E1072="NGHỈ BÁN", 0, IF(K2:K1072="",, IF(ISNUMBER(SEARCH("Cá hồi", F2:F1072)), K2:K1072*22000, K2:K1072*20000)))} -> 0
A3: 2 | B3: 46104 | C3: Sáng | D3: XĐ CT | E3: NGHỈ BÁN | F3: 🧀Pate phô mai kéo sợi | K3: 0 | L3: 0
A4: 3 | B4: 46104 | C4: Sáng | D4: XĐ CT | E4: NGHỈ BÁN | F4: 🐷Heo cao bồi xúc xích | K4: 0 | L4: 0
A5: 4 | B5: 46104 | C5: Sáng | D5: XĐ CT | E5: NGHỈ BÁN | F5: 🐔Gà tomyum | K5: 0 | L5: 0
A6: 5 | B6: 46104 | C6: Sáng | D6: XĐ CT | E6: NGHỈ BÁN | F6: 🐔 Gà teriyaki | K6: 0 | L6: 0
A7: 6 | B7: 46104 | C7: Sáng | D7: XĐ CT | E7: NGHỈ BÁN | F7: 🐮Bò BBQ | K7: 0 | L7: 0
A8: 7 | B8: 46104 | C8: Sáng | D8: XĐ CT | E8: NGHỈ BÁN | F8: 🦐Tôm đút lò | K8: 0 | L8: 0
A9: 8 | B9: 46104 | C9: Sáng | D9: XĐ CT | E9: NGHỈ BÁN | F9: 🎏Cá ngừ | K9: 0 | L9: 0
A10: 9 | B10: 46104 | C10: Sáng | D10: XĐ CT | E10: NGHỈ BÁN | F10: 🥘Chả cá xốt cay | K10: 0 | L10: 0
A11: 10 | B11: 46104 | C11: Sáng | D11: XĐ CT | E11: NGHỈ BÁN | F11: 🌮 Trứng xúc xích mayo | K11: 0 | L11: 0
A12: 11 | B12: 46104 | C12: Sáng | D12: XĐ CT | E12: NGHỈ BÁN | F12: 🍣Cá hồi mayo | K12: 0 | L12: 0
A13: 12 | B13: 46104 | C13: Sáng | D13: XĐ CT | E13: NGHỈ BÁN | F13: 🌭 Xúc xích siêu phomai | K13: 0 | L13: 0
A14: 13 | B14: 46104 | C14: Chiều | D14: XĐ CT | E14: Lưu Quỳnh Nga | F14: Thanh cua trứng Mayo | G14: =I2 | H14: 3 | I14: 2 | K14: 1 | L14: 20000
A15: 14 | B15: 46104 | C15: Chiều | D15: XĐ CT | E15: Lưu Quỳnh Nga | F15: 🧀Pate phô mai kéo sợi | G15: =I3 | K15: 0 | L15: 0
A16: 15 | B16: 46104 | C16: Chiều | D16: XĐ CT | E16: Lưu Quỳnh Nga | F16: 🐷Heo cao bồi xúc xích | G16: =I4 | H16: 1 | I16: 1 | K16: 0 | L16: 0
A17: 16 | B17: 46104 | C17: Chiều | D17: XĐ CT | E17: Lưu Quỳnh Nga | F17: 🐔Gà tomyum | G17: =I5 | H17: 2 | I17: 1 | K17: 1 | L17: 20000
A18: 17 | B18: 46104 | C18: Chiều | D18: XĐ CT | E18: Lưu Quỳnh Nga | F18: 🐔 Gà teriyaki | G18: =I6 | H18: 2 | K18: 2 | L18: 40000
A19: 18 | B19: 46104 | C19: Chiều | D19: XĐ CT | E19: Lưu Quỳnh Nga | F19: 🐮Bò BBQ | G19: =I7 | H19: 2 | I19: 2 | K19: 0 | L19: 0
A20: 19 | B20: 46104 | C20: Chiều | D20: XĐ CT | E20: Lưu Quỳnh Nga | F20: 🦐Tôm đút lò | G20: =I8 | H20: 1 | I20: 1 | K20: 0 | L20: 0
A21: 20 | B21: 46104 | C21: Chiều | D21: XĐ CT | E21: Lưu Quỳnh Nga | F21: 🎏Cá ngừ | G21: =I9 | H21: 1 | I21: 1 | K21: 0 | L21: 0
A22: 21 | B22: 46104 | C22: Chiều | D22: XĐ CT | E22: Lưu Quỳnh Nga | F22: 🥘Chả cá xốt cay | G22: =I10 | K22: 0 | L22: 0
A23: 22 | B23: 46104 | C23: Chiều | D23: XĐ CT | E23: Lưu Quỳnh Nga | F23: 🌮 Trứng xúc xích mayo | G23: =I11 | K23: 0 | L23: 0
A24: 23 | B24: 46104 | C24: Chiều | D24: XĐ CT | E24: Lưu Quỳnh Nga | F24: 🍣Cá hồi mayo | G24: =I12 | K24: 0 | L24: 0
A25: 24 | B25: 46104 | C25: Chiều | D25: XĐ CT | E25: Lưu Quỳnh Nga | F25: 🌭 Xúc xích siêu phomai | G25: =I13 | H25: 15 | I25: 4 | K25: 11 | L25: 220000
A26: 25 | B26: 46104 | C26: Sáng | D26: XĐ CS | E26: NGHỈ BÁN | F26: Thanh cua trứng Mayo | K26: 0 | L26: 0
A27: 26 | B27: 46104 | C27: Sáng | D27: XĐ CS | E27: NGHỈ BÁN | F27: 🧀Pate phô mai kéo sợi | K27: 0 | L27: 0
A28: 27 | B28: 46104 | C28: Sáng | D28: XĐ CS | E28: NGHỈ BÁN | F28: 🐷Heo cao bồi xúc xích | K28: 0 | L28: 0
A29: 28 | B29: 46104 | C29: Sáng | D29: XĐ CS | E29: NGHỈ BÁN | F29: 🐔Gà tomyum | K29: 0 | L29: 0
A30: 29 | B30: 46104 | C30: Sáng | D30: XĐ CS | E30: NGHỈ BÁN | F30: 🐔 Gà teriyaki | K30: 0 | L30: 0
A31: 30 | B31: 46104 | C31: Sáng | D31: XĐ CS | E31: NGHỈ BÁN | F31: 🐮Bò BBQ | K31: 0 | L31: 0
A32: 31 | B32: 46104 | C32: Sáng | D32: XĐ CS | E32: NGHỈ BÁN | F32: 🦐Tôm đút lò | K32: 0 | L32: 0
A33: 32 | B33: 46104 | C33: Sáng | D33: XĐ CS | E33: NGHỈ BÁN | F33: 🎏Cá ngừ | K33: 0 | L33: 0
A34: 33 | B34: 46104 | C34: Sáng | D34: XĐ CS | E34: NGHỈ BÁN | F34: 🥘Chả cá xốt cay | K34: 0 | L34: 0
A35: 34 | B35: 46104 | C35: Sáng | D35: XĐ CS | E35: NGHỈ BÁN | F35: 🌮 Trứng xúc xích mayo | K35: 0 | L35: 0
A36: 35 | B36: 46104 | C36: Sáng | D36: XĐ CS | E36: NGHỈ BÁN | F36: 🍣Cá hồi mayo | K36: 0 | L36: 0
A37: 36 | B37: 46104 | C37: Sáng | D37: XĐ CS | E37: NGHỈ BÁN | F37: 🌭 Xúc xích siêu phomai | K37: 0 | L37: 0
A38: 37 | B38: 46104 | C38: Chiều | D38: XĐ CS | E38: Hoàng Vân Anh | F38: Thanh cua trứng Mayo | G38: =I26 | H38: 5 | I38: 1 | K38: 4 | L38: 80000
A39: 38 | B39: 46104 | C39: Chiều | D39: XĐ CS | E39: Hoàng Vân Anh | F39: 🧀Pate phô mai kéo sợi | G39: =I27 | H39: 2 | I39: 1 | K39: 1 | L39: 20000
A40: 39 | B40: 46104 | C40: Chiều | D40: XĐ CS | E40: Hoàng Vân Anh | F40: 🐷Heo cao bồi xúc xích | G40: =I28 | H40: 2 | I40: 2 | K40: 0 | L40: 0
...

Sheet Lương&Thưởng
A1: STT | B1: Tên NV | C1: Trạng thái | D1: Tổng Ca Làm
B2: Phùng Hà My | C2: CT | D2: =COUNTIF('Nhật ký bán hàng T3'!E:E, B2) -> 59
B3: Ninh Thị Diệu Anh | C3: CT
B4: Hoàng Vân Anh | C4: CT
B5: Nguyễn Ánh Hồng | C5: CT
B6: Dương Tuấn Định | C6: CT
B7: Trịnh Thị Ngọc Minh | C7: CT
B8: Lưu Quỳnh Nga | C8: CT
B9: Ngọc Ánh | C9: CT
B10: Tạ Thị Ngọc Hà | C10: CT
B11: Lưu Thị Mỹ Duyên | C11: CT
B12: Nguyễn Thị Kim Ngân | C12: HV
B13: Nguyễn Thị Chúc An | C13: HV
B14: Lưu Doãn Hoài Nam | C14: HV
